<!--environment for testing-->
<!--door: mass-30kg, width-1.05m, thickness-4.5cm, height-2.1m, color-dark grey-->
<!--door hinge: spring reference-3, spring stiffness-1-->
<!--door frame: color-black-->
<!--door handle: color-gold-->
<!--wall: color-green-->
<!--lighting: one light in room-constant=0.2-->

<sdf version='1.6'>
  <world name='default'>
    <include>
      <uri>model://ground_plane</uri>
    </include>
    <model name="hinged_door">
      <link name="frame">
        <pose>0.0 0 0 0 0 0</pose>
        <collision name="collision">
          <pose>0 0 0 0 0 0</pose>
          <geometry>
            <mesh>
              <uri>file://media/materials/obj/frame_105.obj</uri>
              <scale>0.01 0.01 0.01</scale>
            </mesh>
          </geometry>
        </collision>
        <visual name="visual">
          <pose>0 0 0 0 0 0</pose>
          <geometry>
            <mesh>
              <uri>file://media/materials/obj/frame_105.obj</uri>
              <scale>0.01 0.01 0.01</scale>
            </mesh>
          </geometry>
          <material>
           <script>
            <uri>file://media/materials/scripts/Gazebo.material</uri>
            <name>Gazebo/Black</name>
           </script>
          </material>
        </visual>
      </link>
      <link name="door">
        <pose>-0.045 0 0 0 0 0</pose>
        <inertial>
          <mass>30</mass>
          <pose>0 0 0 0 0 0</pose>
          <inertia>
            <ixx>14.7</ixx>
            <ixy>-0.000861</ixy>
            <ixz>0</ixz>
            <iyy>17.4</iyy>
            <iyz>0</iyz>
            <izz>2.70675</izz>
          </inertia>
        </inertial>
        <collision name="collision">
          <pose>0 0 0 0 0 0</pose>
          <geometry>
            <mesh>
              <uri>file://media/materials/obj/door_105.obj</uri>
              <scale>0.01 0.01 0.01</scale>
            </mesh>
          </geometry>
        </collision>
        <visual name="visual">
          <pose>0 0 0 0 0 0</pose>
          <geometry>
            <mesh>
              <uri>file://media/materials/obj/door_105.obj</uri>
              <scale>0.01 0.01 0.01</scale>
            </mesh>
          </geometry>
          <material>
           <script>
            <uri>file://media/materials/scripts/Gazebo.material</uri>
            <name>Gazebo/DarkGrey</name>
           </script>
          </material>
        </visual>
      </link>
      <link name="handle">
        <pose>0.9 -0.045 0.95 0 0 0</pose>
        <inertial>
          <mass>1</mass>
          <pose>0 0 0 0 0 0</pose>
          <inertia>
            <ixx>1</ixx>
            <ixy>0</ixy>
            <ixz>0</ixz>
            <iyy>1</iyy>
            <iyz>0</iyz>
            <izz>1</izz>
          </inertia>
        </inertial>
        <collision name="collision_1">
          <pose>0 0 0 0 0 -1.57</pose>
          <geometry>
            <mesh>
              <uri>file://media/materials/obj/handle.obj</uri>
              <scale>0.01 0.01 0.01</scale>
            </mesh>
          </geometry>
        </collision>
        <collision name="collision_2">
          <pose>0 0.045 0 3.14 0 1.57</pose>
          <geometry>
            <mesh>
              <uri>file://media/materials/obj/handle.obj</uri>
              <scale>0.01 0.01 0.01</scale>
            </mesh>
          </geometry>
        </collision>
        <visual name="visual_1">
          <pose>0 0 0 0 0 -1.57</pose>
          <geometry>
            <mesh>
              <uri>file://media/materials/obj/handle.obj</uri>
              <scale>0.01 0.01 0.01</scale>
            </mesh>
          </geometry>
          <material>
          <script>
            <uri>file://media/materials/scripts/Gazebo.material</uri>
            <name>Gazebo/Gold</name>
          </script>
          </material>
        </visual>
        <visual name="visual_2">
          <pose>0 0.045 0 3.14 0 1.57</pose>
          <geometry>
            <mesh>
              <uri>file://media/materials/obj/handle.obj</uri>
              <scale>0.01 0.01 0.01</scale>
            </mesh>
          </geometry>
          <material>
          <script>
            <uri>file://media/materials/scripts/Gazebo.material</uri>
            <name>Gazebo/Gold</name>
          </script>
          </material>
        </visual>
      </link>
      <joint name="door_handle" type="revolute">
        <parent>door</parent>
        <child>handle</child>
        <pose>0 0 0 0 0 0</pose>
        <axis>
          <xyz>0 1 0</xyz>
          <limit>
            <lower>-1</lower>
            <upper>0</upper>
            <effort>0</effort>
            <stiffness>0</stiffness>
            <dissipation>0</dissipation>
          </limit>
          <dynamics>
            <spring_reference>0</spring_reference>
            <spring_stiffness>1</spring_stiffness>
            <damping>0</damping>
            <friction>0</friction>
          </dynamics>
          <use_parent_model_frame>true</use_parent_model_frame>
        </axis>
      </joint>
      <joint name="hinge" type="revolute">
        <parent>frame</parent>
        <child>door</child>
        <pose>0 0 1.05 0 0 0</pose>
        <axis>
          <xyz>0 0 1</xyz>
          <limit>
            <lower>0</lower>
            <upper>1.47</upper>
            <effort>0</effort>
            <stiffness>0</stiffness>
            <dissipation>0</dissipation>
          </limit>
          <dynamics>
            <spring_reference>3</spring_reference>
            <spring_stiffness>1</spring_stiffness>
            <damping>0</damping>
            <friction>0</friction>
          </dynamics>
          <use_parent_model_frame>true</use_parent_model_frame>
        </axis>
      </joint>
      <joint name="world_joint" type="fixed">
        <child>frame</child>
        <parent>world</parent>
      </joint>
    </model>
    <model name="walls">
      <static>true</static>
      <link name="wall_1">
        <collision name="wall_1_collision">
          <pose>-0.03 2.055 1.08 0 0 0</pose>
          <geometry>
            <box>
              <size>0.1 1.88 2.16</size>
            </box>
          </geometry>
        </collision>
        <visual name="wall_1_visual">
          <pose>-0.03 2.055 1.08 0 0 0</pose>
          <geometry>
            <box>
              <size>0.1 1.88 2.16</size>
            </box>
          </geometry>
          <material>
            <script>
              <uri>file://media/materials/scripts/Gazebo.material</uri>
              <name>Gazebo/Green</name>
            </script>
          </material>
        </visual>
      </link>
      <link name="wall_2">
        <collision name="wall_2_collision">
          <pose>-0.03 -0.53 1.08 0 0 0</pose>
          <geometry>
            <box>
              <size>0.1 0.93 2.16</size>
            </box>
          </geometry>
        </collision>
        <visual name="wall_2_visual">
          <pose>-0.03 -0.53 1.08 0 0 0</pose>
          <geometry>
            <box>
              <size>0.1 0.93 2.16</size>
            </box>
          </geometry>
          <material>
            <script>
              <uri>file://media/materials/scripts/Gazebo.material</uri>
              <name>Gazebo/Green</name>
            </script>
          </material>
        </visual>
      </link>
      <link name="wall_3">
        <collision name="wall_3_collision">
          <pose>2 3.05 1.08 0 0 0</pose>
          <geometry>
            <box>
              <size>4 0.1 2.16</size>
            </box>
          </geometry>
        </collision>
        <visual name="wall_3_visual">
          <pose>2 3.05 1.08 0 0 0</pose>
          <geometry>
            <box>
              <size>4 0.1 2.16</size>
            </box>
          </geometry>
          <material>
            <script>
              <uri>file://media/materials/scripts/Gazebo.material</uri>
              <name>Gazebo/Green</name>
            </script>
          </material>
        </visual>
      </link>
      <link name="wall_4">
        <collision name="wall_4_collision">
          <pose>2 -1.05 1.08 0 0 0</pose>
          <geometry>
            <box>
              <size>4.0 0.1 2.16</size>
            </box>
          </geometry>
        </collision>
        <visual name="wall_4_visual">
          <pose>2 -1.05 1.08 0 0 0</pose>
          <geometry>
            <box>
              <size>4.0 0.1 2.16</size>
            </box>
          </geometry>
          <material>
            <script>
              <uri>file://media/materials/scripts/Gazebo.material</uri>
              <name>Gazebo/Green</name>
            </script>
          </material>
        </visual>
      </link>
      <link name="wall_5">
        <collision name="wall_5_collision">
          <pose>3.95 1 1.08 0 0 0</pose>
          <geometry>
            <box>
              <size>0.1 4 2.16</size>
            </box>
          </geometry>
        </collision>
        <visual name="wall_5_visual">
          <pose>3.95 1 1.08 0 0 0</pose>
          <geometry>
            <box>
              <size>0.1 4 2.16</size>
            </box>
          </geometry>
          <material>
            <script>
              <uri>file://media/materials/scripts/Gazebo.material</uri>
              <name>Gazebo/Green</name>
            </script>
          </material>
        </visual>
      </link>
      <link name="wall_6">
        <collision name="wall_6_collision">
          <pose>-1.95 1.0 1.08 0 0 0</pose>
          <geometry>
            <box>
              <size>0.1 5 2.16</size>
            </box>
          </geometry>
        </collision>
        <visual name="wall_6_visual">
          <pose>-1.95 1 1.08 0 0 0</pose>
          <geometry>
            <box>
              <size>0.1 5 2.16</size>
            </box>
          </geometry>
          <material>
            <script>
              <uri>file://media/materials/scripts/Gazebo.material</uri>
              <name>Gazebo/Green</name>
            </script>
          </material>
        </visual>
      </link>
    </model>
    <model name="socket">
      <static>true</static>
      <link name="socket_1">
        <visual name="visual_socket_1">
          <pose>-1.88 1.5 0.4 1.57 0 1.57</pose>
          <geometry>
            <mesh>
              <uri>file://media/materials/obj/socket.obj</uri>
            </mesh>
          </geometry>
          <material>
            <script>
              <uri>file://media/materials/scripts/Gazebo.material</uri>
              <name>Gazebo/Gray</name>
            </script>
          </material>
        </visual>
        <collision name="collision_socket_1">
          <pose>-1.88 1.5 0.4 1.57 0 1.57</pose>
          <geometry>
            <mesh>
              <uri>file://media/materials/obj/socket.obj</uri>
            </mesh>
          </geometry>
        </collision>
      </link>
      <link name="socket_2">
        <visual name="visual_socket_2">
          <pose>1.0 2.98 0.4 1.57 0 0</pose>
          <geometry>
            <mesh>
              <uri>file://media/materials/obj/socket.obj</uri>
            </mesh>
          </geometry>
          <material>
            <script>
              <uri>file://media/materials/scripts/Gazebo.material</uri>
              <name>Gazebo/Gray</name>
            </script>
          </material>
        </visual>
        <collision name="collision_socket_2">
          <pose>1.0 2.98 0.4 1.57 0 0</pose>
          <geometry>
            <mesh>
              <uri>file://media/materials/obj/socket.obj</uri>
            </mesh>
          </geometry>
        </collision>
      </link>
    </model>
    <light name="light0" type="point">
      <cast_shadows>0</cast_shadows>
      <diffuse>1 1 1 1</diffuse>
      <specular>0.1 0.1 0.1 1</specular>
      <pose>2 1 3 0 0 0</pose>
      <direction>0 0 -1</direction>
      <attenuation>
        <range>10</range>
        <linear>0</linear>
        <constant>0.2</constant>
      </attenuation>
    </light>

    <physics type="ode">
      <max_step_size>0.001</max_step_size>
      <real_time_factor>1</real_time_factor>
      <real_time_update_rate>1000</real_time_update_rate>
      <ode>
        <solver>
          <type>quick</type>
          <iters>1000</iters>
          <sor>1.3</sor>
        </solver>
        <constraints>
          <cfm>0</cfm>
          <erp>0.2</erp>
          <contact_max_correcting_vel>100</contact_max_correcting_vel>
          <contact_surface_layer>0.001</contact_surface_layer>
        </constraints>
      </ode>
    </physics>

    <gui fullscreen='0'>
      <camera name='user_camera'>
        <pose frame=''>1.43231 2.17046 6.28176 0 1.2058 -2.42384</pose>
        <view_controller>orbit</view_controller>
        <projection_type>perspective</projection_type>
      </camera>
    </gui>
  </world>
</sdf>
